<robot name="arm">
    <link name="base_link">
      <visual>
        <geometry>
          <box size="1 .3 0.1"/>
        </geometry>
        <material name="silver">
          <color rgba="0 1 1 1"/>
        </material>
          <origin rpy="0 0 0" xyz="0 0 0.025"/>
      </visual>

   
    </link>

  <joint name="fixed" type="fixed">
    <child link="base_link"/>
  </joint>


  <link name="base_rot1">
    <visual>
      <geometry>
        <box size="0.1 0.6 0.05"/>
      </geometry>
      <material name="silver">
        <color rgba="0 1 0.5 0.5"/>
      </material>
        <origin rpy="0 0 0" xyz="0.3 -0.3 0.1"/>

    </visual>
  </link>

  <joint name="base_joint1" type="revolute">
    <parent link="base_link"/>
      <child link="base_rot"/>
      <origin xyz="0 0 0.08" rpy="0 0 0" />
      <axis xyz="0 0 -1"/>
  </joint>

    <link name="base_rot2">
          <visual>
            <geometry>
                <box size="0.1 0.6 0.05"/>
            </geometry>
            <material name="silver">
                <color rgba="0 1 0.5 0.5"/>
            </material>
            <origin rpy="0 0 0" xyz="-0.3 -0.3 0.1"/>
          
          </visual>
      </link>

      <joint name="base_joint2" type="revolute">
        <parent link="base_link"/>
        <child link="base_rot"/>
        <origin xyz="0 0 0.08" rpy="0 0 0" />
        <axis xyz="0 0 -1"/>
      </joint>


      


      <link name="base_rot3">
          <visual>
            <geometry>
                <box size="0.1 0.6 0.05"/>
            </geometry>
            <material name="silver">
                <color rgba="0 1 0.5 0.5"/>
            </material>
            <origin rpy="0 0 -.6" xyz="0.15 -0.8 0.16"/>
          </visual>
      </link>

      <joint name="base_joint3" type="revolute">
        <parent link="base_rot1"/>
        <child link="base_rot"/>
        <origin xyz="0.3 -0.8 0.16" rpy="0 0 1" />
        <axis xyz="0 0 -1"/>
      </joint>








      <link name="base_rot4">
          <visual>
            <geometry>
                <box size="0.1 0.6 0.05"/>
            </geometry>
            <material name="silver">
                <color rgba="0 1 0.5 0.5"/>
            </material>
            <origin rpy="0 0 .6" xyz="-0.15 -0.8 0.16"/>
    
          </visual>
      </link>

      <joint name="base_joint4" type="revolute">
        <parent link="base_rot2"/>
        <child link="base_rot"/>
        <origin xyz="0 0 0.08" rpy="0 0 0" />
        <axis xyz="0 0 -1"/>
      </joint>